Workbook

Sheet Tables
B2: Board 1 | R2: *Low1 run: supply on VLow1 - GND, load on VHigh - GND, LEG1 at duty cycle 1 (key 1)
B3: Vhigh (Low1 run)* | D3: Ihigh (Low1 run)* | F3: Vlow1 (Low1 run)* | H3: Ilow1 (Low1 run)* | J3: Vhigh (Low2 run)** | L3: Ihigh (Low2 run)** | N3: Vlow2 (Low2 run)** | P3: Ilow2 (Low2 run)** | R3: **Low2 run: supply on VLow2 - GND, load on VHigh - GND, LEG2 at duty cycle 1 (key 2)
B4: Vmeas | C4: Vini | D4: Imeas | E4: Iini | F4: Vmeas | G4: Vini | H4: Imeas | I4: Iini | J4: Vmeas | K4: Vini | L4: Imeas | M4: Iini | N4: Vmeas | O4: Vini | P4: Imeas | Q4: Iini
B5: 40 | C5: =AVERAGE('Mesures Low1'!C$3:C$13) -> #DIV/0! | E5: =AVERAGE('Mesures Low1'!F$3:F$13) -> #DIV/0! | G5: =AVERAGE('Mesures Low1'!D$3:D$13) -> #DIV/0! | I5: =AVERAGE('Mesures Low1'!G$3:G$13) -> #DIV/0! | J5: 40 | K5: =AVERAGE('Mesures Low2'!C$3:C$13) -> #DIV/0! | M5: =AVERAGE('Mesures Low2'!F$3:F$13) -> #DIV/0! | O5: =AVERAGE('Mesures Low2'!E$3:E$13) -> #DIV/0! | Q5: =AVERAGE('Mesures Low2'!H$3:H$13) -> #DIV/0!
B6: 45 | C6: =AVERAGE('Mesures Low1'!C$15:C$25) -> #DIV/0! | E6: =AVERAGE('Mesures Low1'!F$15:F$25) -> #DIV/0! | G6: =AVERAGE('Mesures Low1'!D$15:D$25) -> #DIV/0! | I6: =AVERAGE('Mesures Low1'!G$15:G$25) -> #DIV/0! | J6: 45 | K6: =AVERAGE('Mesures Low2'!C$15:C$25) -> #DIV/0! | M6: =AVERAGE('Mesures Low2'!F$15:F$25) -> #DIV/0! | O6: =AVERAGE('Mesures Low2'!E$15:E$25) -> #DIV/0! | Q6: =AVERAGE('Mesures Low2'!H$15:H$25) -> #DIV/0!
B7: 50 | C7: =AVERAGE('Mesures Low1'!C$27:C$37) -> #DIV/0! | E7: =AVERAGE('Mesures Low1'!F$27:F$37) -> #DIV/0! | G7: =AVERAGE('Mesures Low1'!D$27:D$37) -> #DIV/0! | I7: =AVERAGE('Mesures Low1'!G$27:G$37) -> #DIV/0! | J7: 50 | K7: =AVERAGE('Mesures Low2'!C$27:C$37) -> #DIV/0! | M7: =AVERAGE('Mesures Low2'!F$27:F$37) -> #DIV/0! | O7: =AVERAGE('Mesures Low2'!E$27:E$37) -> #DIV/0! | Q7: =AVERAGE('Mesures Low2'!H$27:H$37) -> #DIV/0!
B8: 55 | C8: =AVERAGE('Mesures Low1'!C$39:C$49) -> #DIV/0! | E8: =AVERAGE('Mesures Low1'!F$39:F$49) -> #DIV/0! | G8: =AVERAGE('Mesures Low1'!D$39:D$49) -> #DIV/0! | I8: =AVERAGE('Mesures Low1'!G$39:G$49) -> #DIV/0! | J8: 55 | K8: =AVERAGE('Mesures Low2'!C$39:C$49) -> #DIV/0! | M8: =AVERAGE('Mesures Low2'!F$39:F$49) -> #DIV/0! | O8: =AVERAGE('Mesures Low2'!E$39:E$49) -> #DIV/0! | Q8: =AVERAGE('Mesures Low2'!H$39:H$49) -> #DIV/0!
B9: 60 | C9: =AVERAGE('Mesures Low1'!C$51:C$61) -> #DIV/0! | E9: =AVERAGE('Mesures Low1'!F$51:F$61) -> #DIV/0! | G9: =AVERAGE('Mesures Low1'!D$51:D$61) -> #DIV/0! | I9: =AVERAGE('Mesures Low1'!G$51:G$61) -> #DIV/0! | J9: 60 | K9: =AVERAGE('Mesures Low2'!C$51:C$61) -> #DIV/0! | M9: =AVERAGE('Mesures Low2'!F$51:F$61) -> #DIV/0! | O9: =AVERAGE('Mesures Low2'!E$51:E$61) -> #DIV/0! | Q9: =AVERAGE('Mesures Low2'!H$51:H$61) -> #DIV/0!
B10: Board 2
B11: Vhigh (Low1 run)* | D11: Ihigh (Low1 run)* | F11: Vlow1 (Low1 run)* | H11: Ilow1 (Low1 run)* | J11: Vhigh (Low2 run)** | L11: Ihigh (Low2 run)** | N11: Vlow2 (Low2 run)** | P11: Ilow2 (Low2 run)**
B12: Vmeas | C12: Vini | D12: Imeas | E12: Iini | F12: Vmeas | G12: Vini | H12: Imeas | I12: Iini | J12: Vmeas | K12: Vini | L12: Imeas | M12: Iini | N12: Vmeas | O12: Vini | P12: Imeas | Q12: Iini
B13: 40 | C13: =AVERAGE('Mesures Low1'!K$3:K$13) -> #DIV/0! | E13: =AVERAGE('Mesures Low1'!N$3:N$13) -> #DIV/0! | G13: =AVERAGE('Mesures Low1'!L$3:L$13) -> #DIV/0! | I13: =AVERAGE('Mesures Low1'!O$3:O$13) -> #DIV/0! | J13: 40 | K13: =AVERAGE('Mesures Low2'!K$3:K$13) -> #DIV/0! | M13: =AVERAGE('Mesures Low2'!N$3:N$13) -> #DIV/0! | O13: =AVERAGE('Mesures Low2'!M$3:M$13) -> #DIV/0! | Q13: =AVERAGE('Mesures Low2'!P$3:P$13) -> #DIV/0!
B14: 45 | C14: =AVERAGE('Mesures Low1'!K$15:K$25) -> #DIV/0! | E14: =AVERAGE('Mesures Low1'!N$15:N$25) -> #DIV/0! | G14: =AVERAGE('Mesures Low1'!L$15:L$25) -> #DIV/0! | I14: =AVERAGE('Mesures Low1'!O$15:O$25) -> #DIV/0! | J14: 45 | K14: =AVERAGE('Mesures Low2'!K$15:K$25) -> #DIV/0! | M14: =AVERAGE('Mesures Low2'!N$15:N$25) -> #DIV/0! | O14: =AVERAGE('Mesures Low2'!M$15:M$25) -> #DIV/0! | Q14: =AVERAGE('Mesures Low2'!P$15:P$25) -> #DIV/0!
B15: 50 | C15: =AVERAGE('Mesures Low1'!K$27:K$37) -> #DIV/0! | E15: =AVERAGE('Mesures Low1'!N$27:N$37) -> #DIV/0! | G15: =AVERAGE('Mesures Low1'!L$27:L$37) -> #DIV/0! | I15: =AVERAGE('Mesures Low1'!O$27:O$37) -> #DIV/0! | J15: 50 | K15: =AVERAGE('Mesures Low2'!K$27:K$37) -> #DIV/0! | M15: =AVERAGE('Mesures Low2'!N$27:N$37) -> #DIV/0! | O15: =AVERAGE('Mesures Low2'!M$27:M$37) -> #DIV/0! | Q15: =AVERAGE('Mesures Low2'!P$27:P$37) -> #DIV/0!
B16: 55 | C16: =AVERAGE('Mesures Low1'!K$39:K$49) -> #DIV/0! | E16: =AVERAGE('Mesures Low1'!N$39:N$49) -> #DIV/0! | G16: =AVERAGE('Mesures Low1'!L$39:L$49) -> #DIV/0! | I16: =AVERAGE('Mesures Low1'!O$39:O$49) -> #DIV/0! | J16: 55 | K16: =AVERAGE('Mesures Low2'!K$39:K$49) -> #DIV/0! | M16: =AVERAGE('Mesures Low2'!N$39:N$49) -> #DIV/0! | O16: =AVERAGE('Mesures Low2'!M$39:M$49) -> #DIV/0! | Q16: =AVERAGE('Mesures Low2'!P$39:P$49) -> #DIV/0!
B17: 60 | C17: =AVERAGE('Mesures Low1'!K$51:K$61) -> #DIV/0! | E17: =AVERAGE('Mesures Low1'!N$51:N$61) -> #DIV/0! | G17: =AVERAGE('Mesures Low1'!L$51:L$61) -> #DIV/0! | I17: =AVERAGE('Mesures Low1'!O$51:O$61) -> #DIV/0! | J17: 60 | K17: =AVERAGE('Mesures Low2'!K$51:K$61) -> #DIV/0! | M17: =AVERAGE('Mesures Low2'!N$51:N$61) -> #DIV/0! | O17: =AVERAGE('Mesures Low2'!M$51:M$61) -> #DIV/0! | Q17: =AVERAGE('Mesures Low2'!P$51:P$61) -> #DIV/0!
B18: Board 3
B19: Vhigh (Low1 run)* | D19: Ihigh (Low1 run)* | F19: Vlow1 (Low1 run)* | H19: Ilow1 (Low1 run)* | J19: Vhigh (Low2 run)** | L19: Ihigh (Low2 run)** | N19: Vlow2 (Low2 run)** | P19: Ilow2 (Low2 run)**
B20: Vmeas | C20: Vini | D20: Imeas | E20: Iini | F20: Vmeas | G20: Vini | H20: Imeas | I20: Iini | J20: Vmeas | K20: Vini | L20: Imeas | M20: Iini | N20: Vmeas | O20: Vini | P20: Imeas | Q20: Iini
B21: 40 | C21: =AVERAGE('Mesures Low1'!S$3:S$13) -> #DIV/0! | E21: =AVERAGE('Mesures Low1'!V$3:V$13) -> #DIV/0! | G21: =AVERAGE('Mesures Low1'!T$3:T$13) -> #DIV/0! | I21: =AVERAGE('Mesures Low1'!W$3:W$13) -> #DIV/0! | J21: 40 | K21: =AVERAGE('Mesures Low2'!S$3:S$13) -> #DIV/0! | M21: =AVERAGE('Mesures Low2'!V$3:V$13) -> #DIV/0! | O21: =AVERAGE('Mesures Low2'!U$3:U$13) -> #DIV/0! | Q21: =AVERAGE('Mesures Low2'!X$3:X$13) -> #DIV/0!
B22: 45 | C22: =AVERAGE('Mesures Low1'!S$15:S$25) -> #DIV/0! | E22: =AVERAGE('Mesures Low1'!V$15:V$25) -> #DIV/0! | G22: =AVERAGE('Mesures Low1'!T$15:T$25) -> #DIV/0! | I22: =AVERAGE('Mesures Low1'!W$15:W$25) -> #DIV/0! | J22: 45 | K22: =AVERAGE('Mesures Low2'!S$15:S$25) -> #DIV/0! | M22: =AVERAGE('Mesures Low2'!V$15:V$25) -> #DIV/0! | O22: =AVERAGE('Mesures Low2'!U$15:U$25) -> #DIV/0! | Q22: =AVERAGE('Mesures Low2'!X$15:X$25) -> #DIV/0!
B23: 50 | C23: =AVERAGE('Mesures Low1'!S$27:S$37) -> #DIV/0! | E23: =AVERAGE('Mesures Low1'!V$27:V$37) -> #DIV/0! | G23: =AVERAGE('Mesures Low1'!T$27:T$37) -> #DIV/0! | I23: =AVERAGE('Mesures Low1'!W$27:W$37) -> #DIV/0! | J23: 50 | K23: =AVERAGE('Mesures Low2'!S$27:S$37) -> #DIV/0! | M23: =AVERAGE('Mesures Low2'!V$27:V$37) -> #DIV/0! | O23: =AVERAGE('Mesures Low2'!U$27:U$37) -> #DIV/0! | Q23: =AVERAGE('Mesures Low2'!X$27:X$37) -> #DIV/0!
B24: 55 | C24: =AVERAGE('Mesures Low1'!S$39:S$49) -> #DIV/0! | E24: =AVERAGE('Mesures Low1'!V$39:V$49) -> #DIV/0! | G24: =AVERAGE('Mesures Low1'!T$39:T$49) -> #DIV/0! | I24: =AVERAGE('Mesures Low1'!W$39:W$49) -> #DIV/0! | J24: 55 | K24: =AVERAGE('Mesures Low2'!S$39:S$49) -> #DIV/0! | M24: =AVERAGE('Mesures Low2'!V$39:V$49) -> #DIV/0! | O24: =AVERAGE('Mesures Low2'!U$39:U$49) -> #DIV/0! | Q24: =AVERAGE('Mesures Low2'!X$39:X$49) -> #DIV/0!
B25: 60 | C25: =AVERAGE('Mesures Low1'!S$51:S$61) -> #DIV/0! | E25: =AVERAGE('Mesures Low1'!V$51:V$61) -> #DIV/0! | G25: =AVERAGE('Mesures Low1'!T$51:T$61) -> #DIV/0! | I25: =AVERAGE('Mesures Low1'!W$51:W$61) -> #DIV/0! | J25: 60 | K25: =AVERAGE('Mesures Low2'!S$51:S$61) -> #DIV/0! | M25: =AVERAGE('Mesures Low2'!V$51:V$61) -> #DIV/0! | O25: =AVERAGE('Mesures Low2'!U$51:U$61) -> #DIV/0! | Q25: =AVERAGE('Mesures Low2'!X$51:X$61) -> #DIV/0!
B26: Board 4
B27: Vhigh (Low1 run)* | D27: Ihigh (Low1 run)* | F27: Vlow1 (Low1 run)* | H27: Ilow1 (Low1 run)* | J27: Vhigh (Low2 run)** | L27: Ihigh (Low2 run)** | N27: Vlow2 (Low2 run)** | P27: Ilow2 (Low2 run)**
B28: Vmeas | C28: Vini | D28: Imeas | E28: Iini | F28: Vmeas | G28: Vini | H28: Imeas | I28: Iini | J28: Vmeas | K28: Vini | L28: Imeas | M28: Iini | N28: Vmeas | O28: Vini | P28: Imeas | Q28: Iini
B29: 40 | C29: =AVERAGE('Mesures Low1'!AA$3:AA$13) -> #DIV/0! | E29: =AVERAGE('Mesures Low1'!AD$3:AD$13) -> #DIV/0! | G29: =AVERAGE('Mesures Low1'!AB$3:AB$13) -> #DIV/0! | I29: =AVERAGE('Mesures Low1'!AE$3:AE$13) -> #DIV/0! | J29: 40 | K29: =AVERAGE('Mesures Low2'!AA$3:AA$13) -> #DIV/0! | M29: =AVERAGE('Mesures Low2'!AD$3:AD$13) -> #DIV/0! | O29: =AVERAGE('Mesures Low2'!AC$3:AC$13) -> #DIV/0! | Q29: =AVERAGE('Mesures Low2'!AF$3:AF$13) -> #DIV/0!
B30: 45 | C30: =AVERAGE('Mesures Low1'!AA$15:AA$25) -> #DIV/0! | E30: =AVERAGE('Mesures Low1'!AD$15:AD$25) -> #DIV/0! | G30: =AVERAGE('Mesures Low1'!AB$15:AB$25) -> #DIV/0! | I30: =AVERAGE('Mesures Low1'!AE$15:AE$25) -> #DIV/0! | J30: 45 | K30: =AVERAGE('Mesures Low2'!AA$15:AA$25) -> #DIV/0! | M30: =AVERAGE('Mesures Low2'!AD$15:AD$25) -> #DIV/0! | O30: =AVERAGE('Mesures Low2'!AC$15:AC$25) -> #DIV/0! | Q30: =AVERAGE('Mesures Low2'!AF$15:AF$25) -> #DIV/0!
B31: 50 | C31: =AVERAGE('Mesures Low1'!AA$27:AA$37) -> #DIV/0! | E31: =AVERAGE('Mesures Low1'!AD$27:AD$37) -> #DIV/0! | G31: =AVERAGE('Mesures Low1'!AB$27:AB$37) -> #DIV/0! | I31: =AVERAGE('Mesures Low1'!AE$27:AE$37) -> #DIV/0! | J31: 50 | K31: =AVERAGE('Mesures Low2'!AA$27:AA$37) -> #DIV/0! | M31: =AVERAGE('Mesures Low2'!AD$27:AD$37) -> #DIV/0! | O31: =AVERAGE('Mesures Low2'!AC$27:AC$37) -> #DIV/0! | Q31: =AVERAGE('Mesures Low2'!AF$27:AF$37) -> #DIV/0!
B32: 55 | C32: =AVERAGE('Mesures Low1'!AA$39:AA$49) -> #DIV/0! | E32: =AVERAGE('Mesures Low1'!AD$39:AD$49) -> #DIV/0! | G32: =AVERAGE('Mesures Low1'!AB$39:AB$49) -> #DIV/0! | I32: =AVERAGE('Mesures Low1'!AE$39:AE$49) -> #DIV/0! | J32: 55 | K32: =AVERAGE('Mesures Low2'!AA$39:AA$49) -> #DIV/0! | M32: =AVERAGE('Mesures Low2'!AD$39:AD$49) -> #DIV/0! | O32: =AVERAGE('Mesures Low2'!AC$39:AC$49) -> #DIV/0! | Q32: =AVERAGE('Mesures Low2'!AF$39:AF$49) -> #DIV/0!
B33: 60 | C33: =AVERAGE('Mesures Low1'!AA$51:AA$61) -> #DIV/0! | E33: =AVERAGE('Mesures Low1'!AD$51:AD$61) -> #DIV/0! | G33: =AVERAGE('Mesures Low1'!AB$51:AB$61) -> #DIV/0! | I33: =AVERAGE('Mesures Low1'!AE$51:AE$61) -> #DIV/0! | J33: 60 | K33: =AVERAGE('Mesures Low2'!AA$51:AA$61) -> #DIV/0! | M33: =AVERAGE('Mesures Low2'!AD$51:AD$61) -> #DIV/0! | O33: =AVERAGE('Mesures Low2'!AC$51:AC$61) -> #DIV/0! | Q33: =AVERAGE('Mesures Low2'!AF$51:AF$61) -> #DIV/0!
B34: Board 5
B35: Vhigh (Low1 run)* | D35: Ihigh (Low1 run)* | F35: Vlow1 (Low1 run)* | H35: Ilow1 (Low1 run)* | J35: Vhigh (Low2 run)** | L35: Ihigh (Low2 run)** | N35: Vlow2 (Low2 run)** | P35: Ilow2 (Low2 run)**
B36: Vmeas | C36: Vini | D36: Imeas | E36: Iini | F36: Vmeas | G36: Vini | H36: Imeas | I36: Iini | J36: Vmeas | K36: Vini | L36: Imeas | M36: Iini | N36: Vmeas | O36: Vini | P36: Imeas | Q36: Iini
B37: 40 | C37: =AVERAGE('Mesures Low1'!AI$3:AI$13) -> #DIV/0! | E37: =AVERAGE('Mesures Low1'!AL$3:AL$13) -> #DIV/0! | G37: =AVERAGE('Mesures Low1'!AJ$3:AJ$13) -> #DIV/0! | I37: =AVERAGE('Mesures Low1'!AM$3:AM$13) -> #DIV/0! | J37: 40 | K37: =AVERAGE('Mesures Low2'!AI$3:AI$13) -> #DIV/0! | M37: =AVERAGE('Mesures Low2'!AL$3:AL$13) -> #DIV/0! | O37: =AVERAGE('Mesures Low2'!AK$3:AK$13) -> #DIV/0! | Q37: =AVERAGE('Mesures Low2'!AN$3:AN$13) -> #DIV/0!
B38: 45 | C38: =AVERAGE('Mesures Low1'!AI$15:AI$25) -> #DIV/0! | E38: =AVERAGE('Mesures Low1'!AL$15:AL$25) -> #DIV/0! | G38: =AVERAGE('Mesures Low1'!AJ$15:AJ$25) -> #DIV/0! | I38: =AVERAGE('Mesures Low1'!AM$15:AM$25) -> #DIV/0! | J38: 45 | K38: =AVERAGE('Mesures Low2'!AI$15:AI$25) -> #DIV/0! | M38: =AVERAGE('Mesures Low2'!AL$15:AL$25) -> #DIV/0! | O38: =AVERAGE('Mesures Low2'!AK$15:AK$25) -> #DIV/0! | Q38: =AVERAGE('Mesures Low2'!AN$15:AN$25) -> #DIV/0!
B39: 50 | C39: =AVERAGE('Mesures Low1'!AI$27:AI$37) -> #DIV/0! | E39: =AVERAGE('Mesures Low1'!AL$27:AL$37) -> #DIV/0! | G39: =AVERAGE('Mesures Low1'!AJ$27:AJ$37) -> #DIV/0! | I39: =AVERAGE('Mesures Low1'!AM$27:AM$37) -> #DIV/0! | J39: 50 | K39: =AVERAGE('Mesures Low2'!AI$27:AI$37) -> #DIV/0! | M39: =AVERAGE('Mesures Low2'!AL$27:AL$37) -> #DIV/0! | O39: =AVERAGE('Mesures Low2'!AK$27:AK$37) -> #DIV/0! | Q39: =AVERAGE('Mesures Low2'!AN$27:AN$37) -> #DIV/0!
B40: 55 | C40: =AVERAGE('Mesures Low1'!AI$39:AI$49) -> #DIV/0! | E40: =AVERAGE('Mesures Low1'!AL$39:AL$49) -> #DIV/0! | G40: =AVERAGE('Mesures Low1'!AJ$39:AJ$49) -> #DIV/0! | I40: =AVERAGE('Mesures Low1'!AM$39:AM$49) -> #DIV/0! | J40: 55 | K40: =AVERAGE('Mesures Low2'!AI$39:AI$49) -> #DIV/0! | M40: =AVERAGE('Mesures Low2'!AL$39:AL$49) -> #DIV/0! | O40: =AVERAGE('Mesures Low2'!AK$39:AK$49) -> #DIV/0! | Q40: =AVERAGE('Mesures Low2'!AN$39:AN$49) -> #DIV/0!
B41: 60 | C41: =AVERAGE('Mesures Low1'!AI$51:AI$61) -> #DIV/0! | E41: =AVERAGE('Mesures Low1'!AL$51:AL$61) -> #DIV/0! | G41: =AVERAGE('Mesures Low1'!AJ$51:AJ$61) -> #DIV/0! | I41: =AVERAGE('Mesures Low1'!AM$51:AM$61) -> #DIV/0! | J41: 60 | K41: =AVERAGE('Mesures Low2'!AI$51:AI$61) -> #DIV/0! | M41: =AVERAGE('Mesures Low2'!AL$51:AL$61) -> #DIV/0! | O41: =AVERAGE('Mesures Low2'!AK$51:AK$61) -> #DIV/0! | Q41: =AVERAGE('Mesures Low2'!AN$51:AN$61) -> #DIV/0!
...

Sheet Mesures Low1
B1: Board 1 - Low1 run | J1: Board 2 - Low1 run | R1: Board 3 - Low1 run | Z1: Board 4 - Low1 run | AH1: Board 5 - Low1 run | AP1: Board 6 - Low1 run | AX1: Board 7 - Low1 run | BF1: Board 8 - Low1 run | BN1: Board 9 - Low1 run | BV1: Board 10 - Low1 run | CD1: Board 11 - Low1 run
B2: Udc (V) | C2: Vhigh | D2: V1low | E2: V2low | F2: Ihigh | G2: I1low | H2: I2low | J2: Udc (V) | K2: Vhigh | L2: V1low | M2: V2low | N2: Ihigh | O2: I1low | P2: I2low | R2: Udc (V) | S2: Vhigh | T2: V1low | U2: V2low | V2: Ihigh | W2: I1low | X2: I2low | Z2: Udc (V) | AA2: Vhigh | AB2: V1low | AC2: V2low | AD2: Ihigh | AE2: I1low | AF2: I2low | AH2: Udc (V) | AI2: Vhigh | AJ2: V1low | AK2: V2low | AL2: Ihigh | AM2: I1low | AN2: I2low | AP2: Udc (V) | AQ2: Vhigh | AR2: V1low | AS2: V2low | AT2: Ihigh | AU2: I1low | AV2: I2low | AX2: Udc (V) | AY2: Vhigh | AZ2: V1low | BA2: V2low | BB2: Ihigh | BC2: I1low | BD2: I2low | BF2: Udc (V) | BG2: Vhigh | BH2: V1low | BI2: V2low | BJ2: Ihigh | BK2: I1low | BL2: I2low | BN2: Udc (V) | BO2: Vhigh | BP2: V1low | BQ2: V2low | BR2: Ihigh | BS2: I1low | BT2: I2low | BV2: Udc (V) | BW2: Vhigh | BX2: V1low | BY2: V2low | BZ2: Ihigh | CA2: I1low | CB2: I2low | CD2: Udc (V) | CE2: Vhigh | CF2: V1low | CG2: V2low | CH2: Ihigh | CI2: I1low | CJ2: I2low
A3: Point 1
A15: Point 2
A27: Point 3
A39: Point 4
A51: Point 5
B63: Paste 11 serial monitor lines per point in the Vhigh column of the board, then split them with Data > Text to Columns, delimiter ':'. Column order = firmware print order: V_HIGH:V1_LOW:V2_LOW:I_HIGH:I1_LOW:I2_LOW.

Sheet Mesures Low2
B1: Board 1 - Low2 run | J1: Board 2 - Low2 run | R1: Board 3 - Low2 run | Z1: Board 4 - Low2 run | AH1: Board 5 - Low2 run | AP1: Board 6 - Low2 run | AX1: Board 7 - Low2 run | BF1: Board 8 - Low2 run | BN1: Board 9 - Low2 run | BV1: Board 10 - Low2 run | CD1: Board 11 - Low2 run
B2: Udc (V) | C2: Vhigh | D2: V1low | E2: V2low | F2: Ihigh | G2: I1low | H2: I2low | J2: Udc (V) | K2: Vhigh | L2: V1low | M2: V2low | N2: Ihigh | O2: I1low | P2: I2low | R2: Udc (V) | S2: Vhigh | T2: V1low | U2: V2low | V2: Ihigh | W2: I1low | X2: I2low | Z2: Udc (V) | AA2: Vhigh | AB2: V1low | AC2: V2low | AD2: Ihigh | AE2: I1low | AF2: I2low | AH2: Udc (V) | AI2: Vhigh | AJ2: V1low | AK2: V2low | AL2: Ihigh | AM2: I1low | AN2: I2low | AP2: Udc (V) | AQ2: Vhigh | AR2: V1low | AS2: V2low | AT2: Ihigh | AU2: I1low | AV2: I2low | AX2: Udc (V) | AY2: Vhigh | AZ2: V1low | BA2: V2low | BB2: Ihigh | BC2: I1low | BD2: I2low | BF2: Udc (V) | BG2: Vhigh | BH2: V1low | BI2: V2low | BJ2: Ihigh | BK2: I1low | BL2: I2low | BN2: Udc (V) | BO2: Vhigh | BP2: V1low | BQ2: V2low | BR2: Ihigh | BS2: I1low | BT2: I2low | BV2: Udc (V) | BW2: Vhigh | BX2: V1low | BY2: V2low | BZ2: Ihigh | CA2: I1low | CB2: I2low | CD2: Udc (V) | CE2: Vhigh | CF2: V1low | CG2: V2low | CH2: Ihigh | CI2: I1low | CJ2: I2low
A3: Point 1
A15: Point 2
A27: Point 3
A39: Point 4
A51: Point 5
B63: Paste 11 serial monitor lines per point in the Vhigh column of the board, then split them with Data > Text to Columns, delimiter ':'. Column order = firmware print order: V_HIGH:V1_LOW:V2_LOW:I_HIGH:I1_LOW:I2_LOW.

Sheet Curves Board 1
H2: A_high (Low1) | I2: =SLOPE(Tables!$B$5:$B$9,Tables!$C$5:$C$9) -> #DIV/0! | J2: =REPLACE(I2,2,1,".") -> #DIV/0! | Q2: A_low1 | R2: =SLOPE(Tables!$F$5:$F$9,Tables!$G$5:$G$9) -> #DIV/0! | S2: A_low2 | T2: =SLOPE(Tables!$N$5:$N$9,Tables!$O$5:$O$9) -> #DIV/0!
H3: B_high (Low1) | I3: =INTERCEPT(Tables!$B$5:$B$9,Tables!$C$5:$C$9) -> #DIV/0! | J3: =REPLACE(I3,2,1,".") -> #DIV/0! | Q3: B_low1 | R3: =INTERCEPT(Tables!$F$5:$F$9,Tables!$G$5:$G$9) -> #DIV/0! | S3: B_low2 | T3: =INTERCEPT(Tables!$N$5:$N$9,Tables!$O$5:$O$9) -> #DIV/0!
H4: C_high (Low1) | I4: =SLOPE(Tables!$D$5:$D$9,Tables!$E$5:$E$9) -> #DIV/0! | J4: =REPLACE(I4,2,1,".") -> #DIV/0! | Q4: C_low1 | R4: =SLOPE(Tables!$H$5:$H$9,Tables!$I$5:$I$9) -> #DIV/0! | S4: C_low2 | T4: =SLOPE(Tables!$P$5:$P$9,Tables!$Q$5:$Q$9) -> #DIV/0!
H5: D_high (Low1) | I5: =INTERCEPT(Tables!$D$5:$D$9,Tables!$E$5:$E$9) -> #DIV/0! | J5: =REPLACE(I5,3,1,".") -> #DIV/0! | Q5: D_low1 | R5: =INTERCEPT(Tables!$H$5:$H$9,Tables!$I$5:$I$9) -> #DIV/0! | S5: D_low2 | T5: =INTERCEPT(Tables!$P$5:$P$9,Tables!$Q$5:$Q$9) -> #DIV/0!
H7: A_high (Low2) | I7: =SLOPE(Tables!$J$5:$J$9,Tables!$K$5:$K$9) -> #DIV/0! | J7: =SUBSTITUTE(I7&"",",",".") -> #DIV/0! | R7: =REPLACE(R2,2,1,".") -> #DIV/0! | T7: =REPLACE(T2,2,1,".") -> #DIV/0!
H8: B_high (Low2) | I8: =INTERCEPT(Tables!$J$5:$J$9,Tables!$K$5:$K$9) -> #DIV/0! | J8: =SUBSTITUTE(I8&"",",",".") -> #DIV/0! | R8: =REPLACE(R3,4,1,".") -> #DIV/0! | T8: =REPLACE(T3,4,1,".") -> #DIV/0!
H9: C_high (Low2) | I9: =SLOPE(Tables!$L$5:$L$9,Tables!$M$5:$M$9) -> #DIV/0! | J9: =SUBSTITUTE(I9&"",",",".") -> #DIV/0! | R9: =REPLACE(R4,2,1,".") -> #DIV/0! | T9: =REPLACE(T4,2,1,".") -> #DIV/0!
H10: D_high (Low2) | I10: =INTERCEPT(Tables!$L$5:$L$9,Tables!$M$5:$M$9) -> #DIV/0! | J10: =SUBSTITUTE(I10&"",",",".") -> #DIV/0! | R10: =REPLACE(R5,3,1,".") -> #DIV/0! | T10: =REPLACE(T5,3,1,".") -> #DIV/0!
H12: Low2 - Low1 | R12: shield.sensors.setConversionParametersLinear(V_HIGH,=TEXTE(J2),=TEXTE(J3));
H13: A_high (%) | I13: =IFERROR((I7-I2)/I2,"")
H14: B_high | I14: =IFERROR(I8-I3,"")
H15: C_high (%) | I15: =IFERROR((I9-I4)/I4,"")
H16: D_high | I16: =IFERROR(I10-I5,"")
B32: Lines to paste in setup_routine() (V_HIGH and I_HIGH from the Low1 run):
B33: =IFERROR("shield.sensors.setConversionParametersLinear(V_HIGH, "&SUBSTITUTE(I2&"",",",".")&IF(I2=INT(I2),".0","")&"F"&", "&SUBSTITUTE(I3&"",",",".")&IF(I3=INT(I3),".0","")&"F"&");","// V_HIGH: no data yet") -> // V_HIGH: no data yet
B34: =IFERROR("shield.sensors.setConversionParametersLinear(I_HIGH, "&SUBSTITUTE(I4&"",",",".")&IF(I4=INT(I4),".0","")&"F"&", "&SUBSTITUTE(I5&"",",",".")&IF(I5=INT(I5),".0","")&"F"&");","// I_HIGH: no data yet") -> // I_HIGH: no data yet
B35: =IFERROR("shield.sensors.setConversionParametersLinear(V1_LOW, "&SUBSTITUTE(R2&"",",",".")&IF(R2=INT(R2),".0","")&"F"&", "&SUBSTITUTE(R3&"",",",".")&IF(R3=INT(R3),".0","")&"F"&");","// V1_LOW: no data yet") -> // V1_LOW: no data yet
B36: =IFERROR("shield.sensors.setConversionParametersLinear(I1_LOW, "&SUBSTITUTE(R4&"",",",".")&IF(R4=INT(R4),".0","")&"F"&", "&SUBSTITUTE(R5&"",",",".")&IF(R5=INT(R5),".0","")&"F"&");","// I1_LOW: no data yet") -> // I1_LOW: no data yet
B37: =IFERROR("shield.sensors.setConversionParametersLinear(V2_LOW, "&SUBSTITUTE(T2&"",",",".")&IF(T2=INT(T2),".0","")&"F"&", "&SUBSTITUTE(T3&"",",",".")&IF(T3=INT(T3),".0","")&"F"&");","// V2_LOW: no data yet") -> // V2_LOW: no data yet
B38: =IFERROR("shield.sensors.setConversionParametersLinear(I2_LOW, "&SUBSTITUTE(T4&"",",",".")&IF(T4=INT(T4),".0","")&"F"&", "&SUBSTITUTE(T5&"",",",".")&IF(T5=INT(T5),".0","")&"F"&");","// I2_LOW: no data yet") -> // I2_LOW: no data yet
B40: Alternative V_HIGH and I_HIGH lines (Low2 run):
B41: =IFERROR("shield.sensors.setConversionParametersLinear(V_HIGH, "&SUBSTITUTE(I7&"",",",".")&IF(I7=INT(I7),".0","")&"F"&", "&SUBSTITUTE(I8&"",",",".")&IF(I8=INT(I8),".0","")&"F"&");","// V_HIGH: no data yet") -> // V_HIGH: no data yet
B42: =IFERROR("shield.sensors.setConversionParametersLinear(I_HIGH, "&SUBSTITUTE(I9&"",",",".")&IF(I9=INT(I9),".0","")&"F"&", "&SUBSTITUTE(I10&"",",",".")&IF(I10=INT(I10),".0","")&"F"&");","// I_HIGH: no data yet") -> // I_HIGH: no data yet

Sheet Curves Board 2
H2: A_high (Low1) | I2: =SLOPE(Tables!$B$13:$B$17,Tables!$C$13:$C$17) -> #DIV/0! | J2: =REPLACE(I2,2,1,".") -> #DIV/0! | Q2: A_low1 | R2: =SLOPE(Tables!$F$13:$F$17,Tables!$G$13:$G$17) -> #DIV/0! | S2: A_low2 | T2: =SLOPE(Tables!$N$13:$N$17,Tables!$O$13:$O$17) -> #DIV/0!
H3: B_high (Low1) | I3: =INTERCEPT(Tables!$B$13:$B$17,Tables!$C$13:$C$17) -> #DIV/0! | J3: =REPLACE(I3,2,1,".") -> #DIV/0! | Q3: B_low1 | R3: =INTERCEPT(Tables!$F$13:$F$17,Tables!$G$13:$G$17) -> #DIV/0! | S3: B_low2 | T3: =INTERCEPT(Tables!$N$13:$N$17,Tables!$O$13:$O$17) -> #DIV/0!
H4: C_high (Low1) | I4: =SLOPE(Tables!$D$13:$D$17,Tables!$E$13:$E$17) -> #DIV/0! | J4: =REPLACE(I4,2,1,".") -> #DIV/0! | Q4: C_low1 | R4: =SLOPE(Tables!$H$13:$H$17,Tables!$I$13:$I$17) -> #DIV/0! | S4: C_low2 | T4: =SLOPE(Tables!$P$13:$P$17,Tables!$Q$13:$Q$17) -> #DIV/0!
H5: D_high (Low1) | I5: =INTERCEPT(Tables!$D$13:$D$17,Tables!$E$13:$E$17) -> #DIV/0! | J5: =REPLACE(I5,3,1,".") -> #DIV/0! | Q5: D_low1 | R5: =INTERCEPT(Tables!$H$13:$H$17,Tables!$I$13:$I$17) -> #DIV/0! | S5: D_low2 | T5: =INTERCEPT(Tables!$P$13:$P$17,Tables!$Q$13:$Q$17) -> #DIV/0!
H7: A_high (Low2) | I7: =SLOPE(Tables!$J$13:$J$17,Tables!$K$13:$K$17) -> #DIV/0! | J7: =SUBSTITUTE(I7&"",",",".") -> #DIV/0! | R7: =REPLACE(R2,2,1,".") -> #DIV/0! | T7: =REPLACE(T2,2,1,".") -> #DIV/0!
H8: B_high (Low2) | I8: =INTERCEPT(Tables!$J$13:$J$17,Tables!$K$13:$K$17) -> #DIV/0! | J8: =SUBSTITUTE(I8&"",",",".") -> #DIV/0! | R8: =REPLACE(R3,4,1,".") -> #DIV/0! | T8: =REPLACE(T3,4,1,".") -> #DIV/0!
H9: C_high (Low2) | I9: =SLOPE(Tables!$L$13:$L$17,Tables!$M$13:$M$17) -> #DIV/0! | J9: =SUBSTITUTE(I9&"",",",".") -> #DIV/0! | R9: =REPLACE(R4,2,1,".") -> #DIV/0! | T9: =REPLACE(T4,2,1,".") -> #DIV/0!
H10: D_high (Low2) | I10: =INTERCEPT(Tables!$L$13:$L$17,Tables!$M$13:$M$17) -> #DIV/0! | J10: =SUBSTITUTE(I10&"",",",".") -> #DIV/0! | R10: =REPLACE(R5,3,1,".") -> #DIV/0! | T10: =REPLACE(T5,3,1,".") -> #DIV/0!
H12: Low2 - Low1
H13: A_high (%) | I13: =IFERROR((I7-I2)/I2,"")
H14: B_high | I14: =IFERROR(I8-I3,"")
H15: C_high (%) | I15: =IFERROR((I9-I4)/I4,"")
H16: D_high | I16: =IFERROR(I10-I5,"")
B32: Lines to paste in setup_routine() (V_HIGH and I_HIGH from the Low1 run):
B33: =IFERROR("shield.sensors.setConversionParametersLinear(V_HIGH, "&SUBSTITUTE(I2&"",",",".")&IF(I2=INT(I2),".0","")&"F"&", "&SUBSTITUTE(I3&"",",",".")&IF(I3=INT(I3),".0","")&"F"&");","// V_HIGH: no data yet") -> // V_HIGH: no data yet
B34: =IFERROR("shield.sensors.setConversionParametersLinear(I_HIGH, "&SUBSTITUTE(I4&"",",",".")&IF(I4=INT(I4),".0","")&"F"&", "&SUBSTITUTE(I5&"",",",".")&IF(I5=INT(I5),".0","")&"F"&");","// I_HIGH: no data yet") -> // I_HIGH: no data yet
B35: =IFERROR("shield.sensors.setConversionParametersLinear(V1_LOW, "&SUBSTITUTE(R2&"",",",".")&IF(R2=INT(R2),".0","")&"F"&", "&SUBSTITUTE(R3&"",",",".")&IF(R3=INT(R3),".0","")&"F"&");","// V1_LOW: no data yet") -> // V1_LOW: no data yet
B36: =IFERROR("shield.sensors.setConversionParametersLinear(I1_LOW, "&SUBSTITUTE(R4&"",",",".")&IF(R4=INT(R4),".0","")&"F"&", "&SUBSTITUTE(R5&"",",",".")&IF(R5=INT(R5),".0","")&"F"&");","// I1_LOW: no data yet") -> // I1_LOW: no data yet
B37: =IFERROR("shield.sensors.setConversionParametersLinear(V2_LOW, "&SUBSTITUTE(T2&"",",",".")&IF(T2=INT(T2),".0","")&"F"&", "&SUBSTITUTE(T3&"",",",".")&IF(T3=INT(T3),".0","")&"F"&");","// V2_LOW: no data yet") -> // V2_LOW: no data yet
B38: =IFERROR("shield.sensors.setConversionParametersLinear(I2_LOW, "&SUBSTITUTE(T4&"",",",".")&IF(T4=INT(T4),".0","")&"F"&", "&SUBSTITUTE(T5&"",",",".")&IF(T5=INT(T5),".0","")&"F"&");","// I2_LOW: no data yet") -> // I2_LOW: no data yet
B40: Alternative V_HIGH and I_HIGH lines (Low2 run):
B41: =IFERROR("shield.sensors.setConversionParametersLinear(V_HIGH, "&SUBSTITUTE(I7&"",",",".")&IF(I7=INT(I7),".0","")&"F"&", "&SUBSTITUTE(I8&"",",",".")&IF(I8=INT(I8),".0","")&"F"&");","// V_HIGH: no data yet") -> // V_HIGH: no data yet
B42: =IFERROR("shield.sensors.setConversionParametersLinear(I_HIGH, "&SUBSTITUTE(I9&"",",",".")&IF(I9=INT(I9),".0","")&"F"&", "&SUBSTITUTE(I10&"",",",".")&IF(I10=INT(I10),".0","")&"F"&");","// I_HIGH: no data yet") -> // I_HIGH: no data yet

Sheet Curves Board 3
H2: A_high (Low1) | I2: =SLOPE(Tables!$B$21:$B$25,Tables!$C$21:$C$25) -> #DIV/0! | J2: =REPLACE(I2,2,1,".") -> #DIV/0! | Q2: A_low1 | R2: =SLOPE(Tables!$F$21:$F$25,Tables!$G$21:$G$25) -> #DIV/0! | S2: A_low2 | T2: =SLOPE(Tables!$N$21:$N$25,Tables!$O$21:$O$25) -> #DIV/0!
H3: B_high (Low1) | I3: =INTERCEPT(Tables!$B$21:$B$25,Tables!$C$21:$C$25) -> #DIV/0! | J3: =REPLACE(I3,2,1,".") -> #DIV/0! | Q3: B_low1 | R3: =INTERCEPT(Tables!$F$21:$F$25,Tables!$G$21:$G$25) -> #DIV/0! | S3: B_low2 | T3: =INTERCEPT(Tables!$N$21:$N$25,Tables!$O$21:$O$25) -> #DIV/0!
H4: C_high (Low1) | I4: =SLOPE(Tables!$D$21:$D$25,Tables!$E$21:$E$25) -> #DIV/0! | J4: =REPLACE(I4,2,1,".") -> #DIV/0! | Q4: C_low1 | R4: =SLOPE(Tables!$H$21:$H$25,Tables!$I$21:$I$25) -> #DIV/0! | S4: C_low2 | T4: =SLOPE(Tables!$P$21:$P$25,Tables!$Q$21:$Q$25) -> #DIV/0!
H5: D_high (Low1) | I5: =INTERCEPT(Tables!$D$21:$D$25,Tables!$E$21:$E$25) -> #DIV/0! | J5: =REPLACE(I5,3,1,".") -> #DIV/0! | Q5: D_low1 | R5: =INTERCEPT(Tables!$H$21:$H$25,Tables!$I$21:$I$25) -> #DIV/0! | S5: D_low2 | T5: =INTERCEPT(Tables!$P$21:$P$25,Tables!$Q$21:$Q$25) -> #DIV/0!
H7: A_high (Low2) | I7: =SLOPE(Tables!$J$21:$J$25,Tables!$K$21:$K$25) -> #DIV/0! | J7: =SUBSTITUTE(I7&"",",",".") -> #DIV/0! | R7: =REPLACE(R2,2,1,".") -> #DIV/0! | T7: =REPLACE(T2,2,1,".") -> #DIV/0!
H8: B_high (Low2) | I8: =INTERCEPT(Tables!$J$21:$J$25,Tables!$K$21:$K$25) -> #DIV/0! | J8: =SUBSTITUTE(I8&"",",",".") -> #DIV/0! | R8: =REPLACE(R3,4,1,".") -> #DIV/0! | T8: =REPLACE(T3,4,1,".") -> #DIV/0!
H9: C_high (Low2) | I9: =SLOPE(Tables!$L$21:$L$25,Tables!$M$21:$M$25) -> #DIV/0! | J9: =SUBSTITUTE(I9&"",",",".") -> #DIV/0! | R9: =REPLACE(R4,2,1,".") -> #DIV/0! | T9: =REPLACE(T4,2,1,".") -> #DIV/0!
H10: D_high (Low2) | I10: =INTERCEPT(Tables!$L$21:$L$25,Tables!$M$21:$M$25) -> #DIV/0! | J10: =SUBSTITUTE(I10&"",",",".") -> #DIV/0! | R10: =REPLACE(R5,3,1,".") -> #DIV/0! | T10: =REPLACE(T5,3,1,".") -> #DIV/0!
H12: Low2 - Low1
H13: A_high (%) | I13: =IFERROR((I7-I2)/I2,"")
H14: B_high | I14: =IFERROR(I8-I3,"")
H15: C_high (%) | I15: =IFERROR((I9-I4)/I4,"")
H16: D_high | I16: =IFERROR(I10-I5,"")
B32: Lines to paste in setup_routine() (V_HIGH and I_HIGH from the Low1 run):
B33: =IFERROR("shield.sensors.setConversionParametersLinear(V_HIGH, "&SUBSTITUTE(I2&"",",",".")&IF(I2=INT(I2),".0","")&"F"&", "&SUBSTITUTE(I3&"",",",".")&IF(I3=INT(I3),".0","")&"F"&");","// V_HIGH: no data yet") -> // V_HIGH: no data yet
B34: =IFERROR("shield.sensors.setConversionParametersLinear(I_HIGH, "&SUBSTITUTE(I4&"",",",".")&IF(I4=INT(I4),".0","")&"F"&", "&SUBSTITUTE(I5&"",",",".")&IF(I5=INT(I5),".0","")&"F"&");","// I_HIGH: no data yet") -> // I_HIGH: no data yet
B35: =IFERROR("shield.sensors.setConversionParametersLinear(V1_LOW, "&SUBSTITUTE(R2&"",",",".")&IF(R2=INT(R2),".0","")&"F"&", "&SUBSTITUTE(R3&"",",",".")&IF(R3=INT(R3),".0","")&"F"&");","// V1_LOW: no data yet") -> // V1_LOW: no data yet
B36: =IFERROR("shield.sensors.setConversionParametersLinear(I1_LOW, "&SUBSTITUTE(R4&"",",",".")&IF(R4=INT(R4),".0","")&"F"&", "&SUBSTITUTE(R5&"",",",".")&IF(R5=INT(R5),".0","")&"F"&");","// I1_LOW: no data yet") -> // I1_LOW: no data yet
B37: =IFERROR("shield.sensors.setConversionParametersLinear(V2_LOW, "&SUBSTITUTE(T2&"",",",".")&IF(T2=INT(T2),".0","")&"F"&", "&SUBSTITUTE(T3&"",",",".")&IF(T3=INT(T3),".0","")&"F"&");","// V2_LOW: no data yet") -> // V2_LOW: no data yet
B38: =IFERROR("shield.sensors.setConversionParametersLinear(I2_LOW, "&SUBSTITUTE(T4&"",",",".")&IF(T4=INT(T4),".0","")&"F"&", "&SUBSTITUTE(T5&"",",",".")&IF(T5=INT(T5),".0","")&"F"&");","// I2_LOW: no data yet") -> // I2_LOW: no data yet
B40: Alternative V_HIGH and I_HIGH lines (Low2 run):
B41: =IFERROR("shield.sensors.setConversionParametersLinear(V_HIGH, "&SUBSTITUTE(I7&"",",",".")&IF(I7=INT(I7),".0","")&"F"&", "&SUBSTITUTE(I8&"",",",".")&IF(I8=INT(I8),".0","")&"F"&");","// V_HIGH: no data yet") -> // V_HIGH: no data yet
B42: =IFERROR("shield.sensors.setConversionParametersLinear(I_HIGH, "&SUBSTITUTE(I9&"",",",".")&IF(I9=INT(I9),".0","")&"F"&", "&SUBSTITUTE(I10&"",",",".")&IF(I10=INT(I10),".0","")&"F"&");","// I_HIGH: no data yet") -> // I_HIGH: no data yet

Sheet Curves Board 4
H2: A_high (Low1) | I2: =SLOPE(Tables!$B$29:$B$33,Tables!$C$29:$C$33) -> #DIV/0! | J2: =REPLACE(I2,2,1,".") -> #DIV/0! | Q2: A_low1 | R2: =SLOPE(Tables!$F$29:$F$33,Tables!$G$29:$G$33) -> #DIV/0! | S2: A_low2 | T2: =SLOPE(Tables!$N$29:$N$33,Tables!$O$29:$O$33) -> #DIV/0!
H3: B_high (Low1) | I3: =INTERCEPT(Tables!$B$29:$B$33,Tables!$C$29:$C$33) -> #DIV/0! | J3: =REPLACE(I3,2,1,".") -> #DIV/0! | Q3: B_low1 | R3: =INTERCEPT(Tables!$F$29:$F$33,Tables!$G$29:$G$33) -> #DIV/0! | S3: B_low2 | T3: =INTERCEPT(Tables!$N$29:$N$33,Tables!$O$29:$O$33) -> #DIV/0!
H4: C_high (Low1) | I4: =SLOPE(Tables!$D$29:$D$33,Tables!$E$29:$E$33) -> #DIV/0! | J4: =REPLACE(I4,2,1,".") -> #DIV/0! | Q4: C_low1 | R4: =SLOPE(Tables!$H$29:$H$33,Tables!$I$29:$I$33) -> #DIV/0! | S4: C_low2 | T4: =SLOPE(Tables!$P$29:$P$33,Tables!$Q$29:$Q$33) -> #DIV/0!
H5: D_high (Low1) | I5: =INTERCEPT(Tables!$D$29:$D$33,Tables!$E$29:$E$33) -> #DIV/0! | J5: =REPLACE(I5,3,1,".") -> #DIV/0! | Q5: D_low1 | R5: =INTERCEPT(Tables!$H$29:$H$33,Tables!$I$29:$I$33) -> #DIV/0! | S5: D_low2 | T5: =INTERCEPT(Tables!$P$29:$P$33,Tables!$Q$29:$Q$33) -> #DIV/0!
H7: A_high (Low2) | I7: =SLOPE(Tables!$J$29:$J$33,Tables!$K$29:$K$33) -> #DIV/0! | J7: =SUBSTITUTE(I7&"",",",".") -> #DIV/0! | R7: =REPLACE(R2,2,1,".") -> #DIV/0! | T7: =REPLACE(T2,2,1,".") -> #DIV/0!
H8: B_high (Low2) | I8: =INTERCEPT(Tables!$J$29:$J$33,Tables!$K$29:$K$33) -> #DIV/0! | J8: =SUBSTITUTE(I8&"",",",".") -> #DIV/0! | R8: =REPLACE(R3,4,1,".") -> #DIV/0! | T8: =REPLACE(T3,4,1,".") -> #DIV/0!
H9: C_high (Low2) | I9: =SLOPE(Tables!$L$29:$L$33,Tables!$M$29:$M$33) -> #DIV/0! | J9: =SUBSTITUTE(I9&"",",",".") -> #DIV/0! | R9: =REPLACE(R4,2,1,".") -> #DIV/0! | T9: =REPLACE(T4,2,1,".") -> #DIV/0!
H10: D_high (Low2) | I10: =INTERCEPT(Tables!$L$29:$L$33,Tables!$M$29:$M$33) -> #DIV/0! | J10: =SUBSTITUTE(I10&"",",",".") -> #DIV/0! | R10: =REPLACE(R5,4,1,".") -> #DIV/0! | T10: =REPLACE(T5,4,1,".") -> #DIV/0!
H12: Low2 - Low1
H13: A_high (%) | I13: =IFERROR((I7-I2)/I2,"")
H14: B_high | I14: =IFERROR(I8-I3,"")
H15: C_high (%) | I15: =IFERROR((I9-I4)/I4,"")
H16: D_high | I16: =IFERROR(I10-I5,"")
B32: Lines to paste in setup_routine() (V_HIGH and I_HIGH from the Low1 run):
B33: =IFERROR("shield.sensors.setConversionParametersLinear(V_HIGH, "&SUBSTITUTE(I2&"",",",".")&IF(I2=INT(I2),".0","")&"F"&", "&SUBSTITUTE(I3&"",",",".")&IF(I3=INT(I3),".0","")&"F"&");","// V_HIGH: no data yet") -> // V_HIGH: no data yet
B34: =IFERROR("shield.sensors.setConversionParametersLinear(I_HIGH, "&SUBSTITUTE(I4&"",",",".")&IF(I4=INT(I4),".0","")&"F"&", "&SUBSTITUTE(I5&"",",",".")&IF(I5=INT(I5),".0","")&"F"&");","// I_HIGH: no data yet") -> // I_HIGH: no data yet
B35: =IFERROR("shield.sensors.setConversionParametersLinear(V1_LOW, "&SUBSTITUTE(R2&"",",",".")&IF(R2=INT(R2),".0","")&"F"&", "&SUBSTITUTE(R3&"",",",".")&IF(R3=INT(R3),".0","")&"F"&");","// V1_LOW: no data yet") -> // V1_LOW: no data yet
B36: =IFERROR("shield.sensors.setConversionParametersLinear(I1_LOW, "&SUBSTITUTE(R4&"",",",".")&IF(R4=INT(R4),".0","")&"F"&", "&SUBSTITUTE(R5&"",",",".")&IF(R5=INT(R5),".0","")&"F"&");","// I1_LOW: no data yet") -> // I1_LOW: no data yet
B37: =IFERROR("shield.sensors.setConversionParametersLinear(V2_LOW, "&SUBSTITUTE(T2&"",",",".")&IF(T2=INT(T2),".0","")&"F"&", "&SUBSTITUTE(T3&"",",",".")&IF(T3=INT(T3),".0","")&"F"&");","// V2_LOW: no data yet") -> // V2_LOW: no data yet
B38: =IFERROR("shield.sensors.setConversionParametersLinear(I2_LOW, "&SUBSTITUTE(T4&"",",",".")&IF(T4=INT(T4),".0","")&"F"&", "&SUBSTITUTE(T5&"",",",".")&IF(T5=INT(T5),".0","")&"F"&");","// I2_LOW: no data yet") -> // I2_LOW: no data yet
B40: Alternative V_HIGH and I_HIGH lines (Low2 run):
B41: =IFERROR("shield.sensors.setConversionParametersLinear(V_HIGH, "&SUBSTITUTE(I7&"",",",".")&IF(I7=INT(I7),".0","")&"F"&", "&SUBSTITUTE(I8&"",",",".")&IF(I8=INT(I8),".0","")&"F"&");","// V_HIGH: no data yet") -> // V_HIGH: no data yet
B42: =IFERROR("shield.sensors.setConversionParametersLinear(I_HIGH, "&SUBSTITUTE(I9&"",",",".")&IF(I9=INT(I9),".0","")&"F"&", "&SUBSTITUTE(I10&"",",",".")&IF(I10=INT(I10),".0","")&"F"&");","// I_HIGH: no data yet") -> // I_HIGH: no data yet

Sheet Curves Board 5
H2: A_high (Low1) | I2: =SLOPE(Tables!$B$37:$B$41,Tables!$C$37:$C$41) -> #DIV/0! | J2: =REPLACE(I2,2,1,".") -> #DIV/0! | Q2: A_low1 | R2: =SLOPE(Tables!$F$37:$F$41,Tables!$G$37:$G$41) -> #DIV/0! | S2: A_low2 | T2: =SLOPE(Tables!$N$37:$N$41,Tables!$O$37:$O$41) -> #DIV/0!
H3: B_high (Low1) | I3: =INTERCEPT(Tables!$B$37:$B$41,Tables!$C$37:$C$41) -> #DIV/0! | J3: =REPLACE(I3,2,1,".") -> #DIV/0! | Q3: B_low1 | R3: =INTERCEPT(Tables!$F$37:$F$41,Tables!$G$37:$G$41) -> #DIV/0! | S3: B_low2 | T3: =INTERCEPT(Tables!$N$37:$N$41,Tables!$O$37:$O$41) -> #DIV/0!
H4: C_high (Low1) | I4: =SLOPE(Tables!$D$37:$D$41,Tables!$E$37:$E$41) -> #DIV/0! | J4: =REPLACE(I4,2,1,".") -> #DIV/0! | Q4: C_low1 | R4: =SLOPE(Tables!$H$37:$H$41,Tables!$I$37:$I$41) -> #DIV/0! | S4: C_low2 | T4: =SLOPE(Tables!$P$37:$P$41,Tables!$Q$37:$Q$41) -> #DIV/0!
H5: D_high (Low1) | I5: =INTERCEPT(Tables!$D$37:$D$41,Tables!$E$37:$E$41) -> #DIV/0! | J5: =REPLACE(I5,3,1,".") -> #DIV/0! | Q5: D_low1 | R5: =INTERCEPT(Tables!$H$37:$H$41,Tables!$I$37:$I$41) -> #DIV/0! | S5: D_low2 | T5: =INTERCEPT(Tables!$P$37:$P$41,Tables!$Q$37:$Q$41) -> #DIV/0!
H7: A_high (Low2) | I7: =SLOPE(Tables!$J$37:$J$41,Tables!$K$37:$K$41) -> #DIV/0! | J7: =SUBSTITUTE(I7&"",",",".") -> #DIV/0! | R7: =REPLACE(R2,2,1,".") -> #DIV/0! | T7: =REPLACE(T2,2,1,".") -> #DIV/0!
H8: B_high (Low2) | I8: =INTERCEPT(Tables!$J$37:$J$41,Tables!$K$37:$K$41) -> #DIV/0! | J8: =SUBSTITUTE(I8&"",",",".") -> #DIV/0! | R8: =REPLACE(R3,4,1,".") -> #DIV/0! | T8: =REPLACE(T3,4,1,".") -> #DIV/0!
H9: C_high (Low2) | I9: =SLOPE(Tables!$L$37:$L$41,Tables!$M$37:$M$41) -> #DIV/0! | J9: =SUBSTITUTE(I9&"",",",".") -> #DIV/0! | R9: =REPLACE(R4,2,1,".") -> #DIV/0! | T9: =REPLACE(T4,2,1,".") -> #DIV/0!
H10: D_high (Low2) | I10: =INTERCEPT(Tables!$L$37:$L$41,Tables!$M$37:$M$41) -> #DIV/0! | J10: =SUBSTITUTE(I10&"",",",".") -> #DIV/0! | R10: =REPLACE(R5,3,1,".") -> #DIV/0! | T10: =REPLACE(T5,3,1,".") -> #DIV/0!
H12: Low2 - Low1
H13: A_high (%) | I13: =IFERROR((I7-I2)/I2,"")
H14: B_high | I14: =IFERROR(I8-I3,"")
H15: C_high (%) | I15: =IFERROR((I9-I4)/I4,"")
H16: D_high | I16: =IFERROR(I10-I5,"")
B32: Lines to paste in setup_routine() (V_HIGH and I_HIGH from the Low1 run):
B33: =IFERROR("shield.sensors.setConversionParametersLinear(V_HIGH, "&SUBSTITUTE(I2&"",",",".")&IF(I2=INT(I2),".0","")&"F"&", "&SUBSTITUTE(I3&"",",",".")&IF(I3=INT(I3),".0","")&"F"&");","// V_HIGH: no data yet") -> // V_HIGH: no data yet
B34: =IFERROR("shield.sensors.setConversionParametersLinear(I_HIGH, "&SUBSTITUTE(I4&"",",",".")&IF(I4=INT(I4),".0","")&"F"&", "&SUBSTITUTE(I5&"",",",".")&IF(I5=INT(I5),".0","")&"F"&");","// I_HIGH: no data yet") -> // I_HIGH: no data yet
B35: =IFERROR("shield.sensors.setConversionParametersLinear(V1_LOW, "&SUBSTITUTE(R2&"",",",".")&IF(R2=INT(R2),".0","")&"F"&", "&SUBSTITUTE(R3&"",",",".")&IF(R3=INT(R3),".0","")&"F"&");","// V1_LOW: no data yet") -> // V1_LOW: no data yet
B36: =IFERROR("shield.sensors.setConversionParametersLinear(I1_LOW, "&SUBSTITUTE(R4&"",",",".")&IF(R4=INT(R4),".0","")&"F"&", "&SUBSTITUTE(R5&"",",",".")&IF(R5=INT(R5),".0","")&"F"&");","// I1_LOW: no data yet") -> // I1_LOW: no data yet
B37: =IFERROR("shield.sensors.setConversionParametersLinear(V2_LOW, "&SUBSTITUTE(T2&"",",",".")&IF(T2=INT(T2),".0","")&"F"&", "&SUBSTITUTE(T3&"",",",".")&IF(T3=INT(T3),".0","")&"F"&");","// V2_LOW: no data yet") -> // V2_LOW: no data yet
B38: =IFERROR("shield.sensors.setConversionParametersLinear(I2_LOW, "&SUBSTITUTE(T4&"",",",".")&IF(T4=INT(T4),".0","")&"F"&", "&SUBSTITUTE(T5&"",",",".")&IF(T5=INT(T5),".0","")&"F"&");","// I2_LOW: no data yet") -> // I2_LOW: no data yet
B40: Alternative V_HIGH and I_HIGH lines (Low2 run):
B41: =IFERROR("shield.sensors.setConversionParametersLinear(V_HIGH, "&SUBSTITUTE(I7&"",",",".")&IF(I7=INT(I7),".0","")&"F"&", "&SUBSTITUTE(I8&"",",",".")&IF(I8=INT(I8),".0","")&"F"&");","// V_HIGH: no data yet") -> // V_HIGH: no data yet
B42: =IFERROR("shield.sensors.setConversionParametersLinear(I_HIGH, "&SUBSTITUTE(I9&"",",",".")&IF(I9=INT(I9),".0","")&"F"&", "&SUBSTITUTE(I10&"",",",".")&IF(I10=INT(I10),".0","")&"F"&");","// I_HIGH: no data yet") -> // I_HIGH: no data yet

Sheet Curves Board 6
H2: A_high (Low1) | I2: =SLOPE(Tables!$B$45:$B$49,Tables!$C$45:$C$49) -> #DIV/0! | J2: =REPLACE(I2,2,1,".") -> #DIV/0! | Q2: A_low1 | R2: =SLOPE(Tables!$F$45:$F$49,Tables!$G$45:$G$49) -> #DIV/0! | S2: A_low2 | T2: =SLOPE(Tables!$N$45:$N$49,Tables!$O$45:$O$49) -> #DIV/0!
H3: B_high (Low1) | I3: =INTERCEPT(Tables!$B$45:$B$49,Tables!$C$45:$C$49) -> #DIV/0! | J3: =REPLACE(I3,2,1,".") -> #DIV/0! | Q3: B_low1 | R3: =INTERCEPT(Tables!$F$45:$F$49,Tables!$G$45:$G$49) -> #DIV/0! | S3: B_low2 | T3: =INTERCEPT(Tables!$N$45:$N$49,Tables!$O$45:$O$49) -> #DIV/0!
H4: C_high (Low1) | I4: =SLOPE(Tables!$D$45:$D$49,Tables!$E$45:$E$49) -> #DIV/0! | J4: =REPLACE(I4,2,1,".") -> #DIV/0! | Q4: C_low1 | R4: =SLOPE(Tables!$H$45:$H$49,Tables!$I$45:$I$49) -> #DIV/0! | S4: C_low2 | T4: =SLOPE(Tables!$P$45:$P$49,Tables!$Q$45:$Q$49) -> #DIV/0!
H5: D_high (Low1) | I5: =INTERCEPT(Tables!$D$45:$D$49,Tables!$E$45:$E$49) -> #DIV/0! | J5: =REPLACE(I5,4,1,".") -> #DIV/0! | Q5: D_low1 | R5: =INTERCEPT(Tables!$H$45:$H$49,Tables!$I$45:$I$49) -> #DIV/0! | S5: D_low2 | T5: =INTERCEPT(Tables!$P$45:$P$49,Tables!$Q$45:$Q$49) -> #DIV/0!
H7: A_high (Low2) | I7: =SLOPE(Tables!$J$45:$J$49,Tables!$K$45:$K$49) -> #DIV/0! | J7: =SUBSTITUTE(I7&"",",",".") -> #DIV/0! | R7: =REPLACE(R2,2,1,".") -> #DIV/0! | T7: =REPLACE(T2,2,1,".") -> #DIV/0!
H8: B_high (Low2) | I8: =INTERCEPT(Tables!$J$45:$J$49,Tables!$K$45:$K$49) -> #DIV/0! | J8: =SUBSTITUTE(I8&"",",",".") -> #DIV/0! | R8: =REPLACE(R3,4,1,".") -> #DIV/0! | T8: =REPLACE(T3,4,1,".") -> #DIV/0!
H9: C_high (Low2) | I9: =SLOPE(Tables!$L$45:$L$49,Tables!$M$45:$M$49) -> #DIV/0! | J9: =SUBSTITUTE(I9&"",",",".") -> #DIV/0! | R9: =REPLACE(R4,2,1,".") -> #DIV/0! | T9: =REPLACE(T4,2,1,".") -> #DIV/0!
H10: D_high (Low2) | I10: =INTERCEPT(Tables!$L$45:$L$49,Tables!$M$45:$M$49) -> #DIV/0! | J10: =SUBSTITUTE(I10&"",",",".") -> #DIV/0! | R10: =REPLACE(R5,4,1,".") -> #DIV/0! | T10: =REPLACE(T5,4,1,".") -> #DIV/0!
H12: Low2 - Low1
H13: A_high (%) | I13: =IFERROR((I7-I2)/I2,"")
H14: B_high | I14: =IFERROR(I8-I3,"")
H15: C_high (%) | I15: =IFERROR((I9-I4)/I4,"")
H16: D_high | I16: =IFERROR(I10-I5,"")
B32: Lines to paste in setup_routine() (V_HIGH and I_HIGH from the Low1 run):
B33: =IFERROR("shield.sensors.setConversionParametersLinear(V_HIGH, "&SUBSTITUTE(I2&"",",",".")&IF(I2=INT(I2),".0","")&"F"&", "&SUBSTITUTE(I3&"",",",".")&IF(I3=INT(I3),".0","")&"F"&");","// V_HIGH: no data yet") -> // V_HIGH: no data yet
B34: =IFERROR("shield.sensors.setConversionParametersLinear(I_HIGH, "&SUBSTITUTE(I4&"",",",".")&IF(I4=INT(I4),".0","")&"F"&", "&SUBSTITUTE(I5&"",",",".")&IF(I5=INT(I5),".0","")&"F"&");","// I_HIGH: no data yet") -> // I_HIGH: no data yet
B35: =IFERROR("shield.sensors.setConversionParametersLinear(V1_LOW, "&SUBSTITUTE(R2&"",",",".")&IF(R2=INT(R2),".0","")&"F"&", "&SUBSTITUTE(R3&"",",",".")&IF(R3=INT(R3),".0","")&"F"&");","// V1_LOW: no data yet") -> // V1_LOW: no data yet
B36: =IFERROR("shield.sensors.setConversionParametersLinear(I1_LOW, "&SUBSTITUTE(R4&"",",",".")&IF(R4=INT(R4),".0","")&"F"&", "&SUBSTITUTE(R5&"",",",".")&IF(R5=INT(R5),".0","")&"F"&");","// I1_LOW: no data yet") -> // I1_LOW: no data yet
B37: =IFERROR("shield.sensors.setConversionParametersLinear(V2_LOW, "&SUBSTITUTE(T2&"",",",".")&IF(T2=INT(T2),".0","")&"F"&", "&SUBSTITUTE(T3&"",",",".")&IF(T3=INT(T3),".0","")&"F"&");","// V2_LOW: no data yet") -> // V2_LOW: no data yet
B38: =IFERROR("shield.sensors.setConversionParametersLinear(I2_LOW, "&SUBSTITUTE(T4&"",",",".")&IF(T4=INT(T4),".0","")&"F"&", "&SUBSTITUTE(T5&"",",",".")&IF(T5=INT(T5),".0","")&"F"&");","// I2_LOW: no data yet") -> // I2_LOW: no data yet
B40: Alternative V_HIGH and I_HIGH lines (Low2 run):
B41: =IFERROR("shield.sensors.setConversionParametersLinear(V_HIGH, "&SUBSTITUTE(I7&"",",",".")&IF(I7=INT(I7),".0","")&"F"&", "&SUBSTITUTE(I8&"",",",".")&IF(I8=INT(I8),".0","")&"F"&");","// V_HIGH: no data yet") -> // V_HIGH: no data yet
B42: =IFERROR("shield.sensors.setConversionParametersLinear(I_HIGH, "&SUBSTITUTE(I9&"",",",".")&IF(I9=INT(I9),".0","")&"F"&", "&SUBSTITUTE(I10&"",",",".")&IF(I10=INT(I10),".0","")&"F"&");","// I_HIGH: no data yet") -> // I_HIGH: no data yet

Sheet Curves Board 7
H2: A_high (Low1) | I2: =SLOPE(Tables!$B$53:$B$57,Tables!$C$53:$C$57) -> #DIV/0! | J2: =REPLACE(I2,2,1,".") -> #DIV/0! | Q2: A_low1 | R2: =SLOPE(Tables!$F$53:$F$57,Tables!$G$53:$G$57) -> #DIV/0! | S2: A_low2 | T2: =SLOPE(Tables!$N$53:$N$57,Tables!$O$53:$O$57) -> #DIV/0!
H3: B_high (Low1) | I3: =INTERCEPT(Tables!$B$53:$B$57,Tables!$C$53:$C$57) -> #DIV/0! | J3: =REPLACE(I3,2,1,".") -> #DIV/0! | Q3: B_low1 | R3: =INTERCEPT(Tables!$F$53:$F$57,Tables!$G$53:$G$57) -> #DIV/0! | S3: B_low2 | T3: =INTERCEPT(Tables!$N$53:$N$57,Tables!$O$53:$O$57) -> #DIV/0!
H4: C_high (Low1) | I4: =SLOPE(Tables!$D$53:$D$57,Tables!$E$53:$E$57) -> #DIV/0! | J4: =REPLACE(I4,2,1,".") -> #DIV/0! | Q4: C_low1 | R4: =SLOPE(Tables!$H$53:$H$57,Tables!$I$53:$I$57) -> #DIV/0! | S4: C_low2 | T4: =SLOPE(Tables!$P$53:$P$57,Tables!$Q$53:$Q$57) -> #DIV/0!
H5: D_high (Low1) | I5: =INTERCEPT(Tables!$D$53:$D$57,Tables!$E$53:$E$57) -> #DIV/0! | J5: =REPLACE(I5,3,1,".") -> #DIV/0! | Q5: D_low1 | R5: =INTERCEPT(Tables!$H$53:$H$57,Tables!$I$53:$I$57) -> #DIV/0! | S5: D_low2 | T5: =INTERCEPT(Tables!$P$53:$P$57,Tables!$Q$53:$Q$57) -> #DIV/0!
H7: A_high (Low2) | I7: =SLOPE(Tables!$J$53:$J$57,Tables!$K$53:$K$57) -> #DIV/0! | J7: =SUBSTITUTE(I7&"",",",".") -> #DIV/0! | R7: =REPLACE(R2,2,1,".") -> #DIV/0! | T7: =REPLACE(T2,2,1,".") -> #DIV/0!
H8: B_high (Low2) | I8: =INTERCEPT(Tables!$J$53:$J$57,Tables!$K$53:$K$57) -> #DIV/0! | J8: =SUBSTITUTE(I8&"",",",".") -> #DIV/0! | R8: =REPLACE(R3,4,1,".") -> #DIV/0! | T8: =REPLACE(T3,4,1,".") -> #DIV/0!
H9: C_high (Low2) | I9: =SLOPE(Tables!$L$53:$L$57,Tables!$M$53:$M$57) -> #DIV/0! | J9: =SUBSTITUTE(I9&"",",",".") -> #DIV/0! | R9: =REPLACE(R4,2,1,".") -> #DIV/0! | T9: =REPLACE(T4,2,1,".") -> #DIV/0!
H10: D_high (Low2) | I10: =INTERCEPT(Tables!$L$53:$L$57,Tables!$M$53:$M$57) -> #DIV/0! | J10: =SUBSTITUTE(I10&"",",",".") -> #DIV/0! | R10: =REPLACE(R5,3,1,".") -> #DIV/0! | T10: =REPLACE(T5,3,1,".") -> #DIV/0!
H12: Low2 - Low1
H13: A_high (%) | I13: =IFERROR((I7-I2)/I2,"")
H14: B_high | I14: =IFERROR(I8-I3,"")
H15: C_high (%) | I15: =IFERROR((I9-I4)/I4,"")
H16: D_high | I16: =IFERROR(I10-I5,"")
B32: Lines to paste in setup_routine() (V_HIGH and I_HIGH from the Low1 run):
B33: =IFERROR("shield.sensors.setConversionParametersLinear(V_HIGH, "&SUBSTITUTE(I2&"",",",".")&IF(I2=INT(I2),".0","")&"F"&", "&SUBSTITUTE(I3&"",",",".")&IF(I3=INT(I3),".0","")&"F"&");","// V_HIGH: no data yet") -> // V_HIGH: no data yet
B34: =IFERROR("shield.sensors.setConversionParametersLinear(I_HIGH, "&SUBSTITUTE(I4&"",",",".")&IF(I4=INT(I4),".0","")&"F"&", "&SUBSTITUTE(I5&"",",",".")&IF(I5=INT(I5),".0","")&"F"&");","// I_HIGH: no data yet") -> // I_HIGH: no data yet
B35: =IFERROR("shield.sensors.setConversionParametersLinear(V1_LOW, "&SUBSTITUTE(R2&"",",",".")&IF(R2=INT(R2),".0","")&"F"&", "&SUBSTITUTE(R3&"",",",".")&IF(R3=INT(R3),".0","")&"F"&");","// V1_LOW: no data yet") -> // V1_LOW: no data yet
B36: =IFERROR("shield.sensors.setConversionParametersLinear(I1_LOW, "&SUBSTITUTE(R4&"",",",".")&IF(R4=INT(R4),".0","")&"F"&", "&SUBSTITUTE(R5&"",",",".")&IF(R5=INT(R5),".0","")&"F"&");","// I1_LOW: no data yet") -> // I1_LOW: no data yet
B37: =IFERROR("shield.sensors.setConversionParametersLinear(V2_LOW, "&SUBSTITUTE(T2&"",",",".")&IF(T2=INT(T2),".0","")&"F"&", "&SUBSTITUTE(T3&"",",",".")&IF(T3=INT(T3),".0","")&"F"&");","// V2_LOW: no data yet") -> // V2_LOW: no data yet
B38: =IFERROR("shield.sensors.setConversionParametersLinear(I2_LOW, "&SUBSTITUTE(T4&"",",",".")&IF(T4=INT(T4),".0","")&"F"&", "&SUBSTITUTE(T5&"",",",".")&IF(T5=INT(T5),".0","")&"F"&");","// I2_LOW: no data yet") -> // I2_LOW: no data yet
B40: Alternative V_HIGH and I_HIGH lines (Low2 run):
B41: =IFERROR("shield.sensors.setConversionParametersLinear(V_HIGH, "&SUBSTITUTE(I7&"",",",".")&IF(I7=INT(I7),".0","")&"F"&", "&SUBSTITUTE(I8&"",",",".")&IF(I8=INT(I8),".0","")&"F"&");","// V_HIGH: no data yet") -> // V_HIGH: no data yet
B42: =IFERROR("shield.sensors.setConversionParametersLinear(I_HIGH, "&SUBSTITUTE(I9&"",",",".")&IF(I9=INT(I9),".0","")&"F"&", "&SUBSTITUTE(I10&"",",",".")&IF(I10=INT(I10),".0","")&"F"&");","// I_HIGH: no data yet") -> // I_HIGH: no data yet

Sheet Curves Board 8
H2: A_high (Low1) | I2: =SLOPE(Tables!$B$61:$B$65,Tables!$C$61:$C$65) -> #DIV/0! | J2: =REPLACE(I2,2,1,".") -> #DIV/0! | Q2: A_low1 | R2: =SLOPE(Tables!$F$61:$F$65,Tables!$G$61:$G$65) -> #DIV/0! | S2: A_low2 | T2: =SLOPE(Tables!$N$61:$N$65,Tables!$O$61:$O$65) -> #DIV/0!
H3: B_high (Low1) | I3: =INTERCEPT(Tables!$B$61:$B$65,Tables!$C$61:$C$65) -> #DIV/0! | J3: =REPLACE(I3,2,1,".") -> #DIV/0! | Q3: B_low1 | R3: =INTERCEPT(Tables!$F$61:$F$65,Tables!$G$61:$G$65) -> #DIV/0! | S3: B_low2 | T3: =INTERCEPT(Tables!$N$61:$N$65,Tables!$O$61:$O$65) -> #DIV/0!
H4: C_high (Low1) | I4: =SLOPE(Tables!$D$61:$D$65,Tables!$E$61:$E$65) -> #DIV/0! | J4: =REPLACE(I4,2,1,".") -> #DIV/0! | Q4: C_low1 | R4: =SLOPE(Tables!$H$61:$H$65,Tables!$I$61:$I$65) -> #DIV/0! | S4: C_low2 | T4: =SLOPE(Tables!$P$61:$P$65,Tables!$Q$61:$Q$65) -> #DIV/0!
H5: D_high (Low1) | I5: =INTERCEPT(Tables!$D$61:$D$65,Tables!$E$61:$E$65) -> #DIV/0! | J5: =REPLACE(I5,3,1,".") -> #DIV/0! | Q5: D_low1 | R5: =INTERCEPT(Tables!$H$61:$H$65,Tables!$I$61:$I$65) -> #DIV/0! | S5: D_low2 | T5: =INTERCEPT(Tables!$P$61:$P$65,Tables!$Q$61:$Q$65) -> #DIV/0!
H7: A_high (Low2) | I7: =SLOPE(Tables!$J$61:$J$65,Tables!$K$61:$K$65) -> #DIV/0! | J7: =SUBSTITUTE(I7&"",",",".") -> #DIV/0! | R7: =REPLACE(R2,2,1,".") -> #DIV/0! | T7: =REPLACE(T2,2,1,".") -> #DIV/0!
H8: B_high (Low2) | I8: =INTERCEPT(Tables!$J$61:$J$65,Tables!$K$61:$K$65) -> #DIV/0! | J8: =SUBSTITUTE(I8&"",",",".") -> #DIV/0! | R8: =REPLACE(R3,4,1,".") -> #DIV/0! | T8: =REPLACE(T3,4,1,".") -> #DIV/0!
H9: C_high (Low2) | I9: =SLOPE(Tables!$L$61:$L$65,Tables!$M$61:$M$65) -> #DIV/0! | J9: =SUBSTITUTE(I9&"",",",".") -> #DIV/0! | R9: =REPLACE(R4,2,1,".") -> #DIV/0! | T9: =REPLACE(T4,2,1,".") -> #DIV/0!
H10: D_high (Low2) | I10: =INTERCEPT(Tables!$L$61:$L$65,Tables!$M$61:$M$65) -> #DIV/0! | J10: =SUBSTITUTE(I10&"",",",".") -> #DIV/0! | R10: =REPLACE(R5,3,1,".") -> #DIV/0! | T10: =REPLACE(T5,3,1,".") -> #DIV/0!
H12: Low2 - Low1
H13: A_high (%) | I13: =IFERROR((I7-I2)/I2,"")
H14: B_high | I14: =IFERROR(I8-I3,"")
H15: C_high (%) | I15: =IFERROR((I9-I4)/I4,"")
H16: D_high | I16: =IFERROR(I10-I5,"")
B32: Lines to paste in setup_routine() (V_HIGH and I_HIGH from the Low1 run):
B33: =IFERROR("shield.sensors.setConversionParametersLinear(V_HIGH, "&SUBSTITUTE(I2&"",",",".")&IF(I2=INT(I2),".0","")&"F"&", "&SUBSTITUTE(I3&"",",",".")&IF(I3=INT(I3),".0","")&"F"&");","// V_HIGH: no data yet") -> // V_HIGH: no data yet
B34: =IFERROR("shield.sensors.setConversionParametersLinear(I_HIGH, "&SUBSTITUTE(I4&"",",",".")&IF(I4=INT(I4),".0","")&"F"&", "&SUBSTITUTE(I5&"",",",".")&IF(I5=INT(I5),".0","")&"F"&");","// I_HIGH: no data yet") -> // I_HIGH: no data yet
B35: =IFERROR("shield.sensors.setConversionParametersLinear(V1_LOW, "&SUBSTITUTE(R2&"",",",".")&IF(R2=INT(R2),".0","")&"F"&", "&SUBSTITUTE(R3&"",",",".")&IF(R3=INT(R3),".0","")&"F"&");","// V1_LOW: no data yet") -> // V1_LOW: no data yet
B36: =IFERROR("shield.sensors.setConversionParametersLinear(I1_LOW, "&SUBSTITUTE(R4&"",",",".")&IF(R4=INT(R4),".0","")&"F"&", "&SUBSTITUTE(R5&"",",",".")&IF(R5=INT(R5),".0","")&"F"&");","// I1_LOW: no data yet") -> // I1_LOW: no data yet
B37: =IFERROR("shield.sensors.setConversionParametersLinear(V2_LOW, "&SUBSTITUTE(T2&"",",",".")&IF(T2=INT(T2),".0","")&"F"&", "&SUBSTITUTE(T3&"",",",".")&IF(T3=INT(T3),".0","")&"F"&");","// V2_LOW: no data yet") -> // V2_LOW: no data yet
B38: =IFERROR("shield.sensors.setConversionParametersLinear(I2_LOW, "&SUBSTITUTE(T4&"",",",".")&IF(T4=INT(T4),".0","")&"F"&", "&SUBSTITUTE(T5&"",",",".")&IF(T5=INT(T5),".0","")&"F"&");","// I2_LOW: no data yet") -> // I2_LOW: no data yet
B40: Alternative V_HIGH and I_HIGH lines (Low2 run):
B41: =IFERROR("shield.sensors.setConversionParametersLinear(V_HIGH, "&SUBSTITUTE(I7&"",",",".")&IF(I7=INT(I7),".0","")&"F"&", "&SUBSTITUTE(I8&"",",",".")&IF(I8=INT(I8),".0","")&"F"&");","// V_HIGH: no data yet") -> // V_HIGH: no data yet
B42: =IFERROR("shield.sensors.setConversionParametersLinear(I_HIGH, "&SUBSTITUTE(I9&"",",",".")&IF(I9=INT(I9),".0","")&"F"&", "&SUBSTITUTE(I10&"",",",".")&IF(I10=INT(I10),".0","")&"F"&");","// I_HIGH: no data yet") -> // I_HIGH: no data yet

Sheet Curves Board 9
H2: A_high (Low1) | I2: =SLOPE(Tables!$B$69:$B$73,Tables!$C$69:$C$73) -> #DIV/0! | J2: =REPLACE(I2,2,1,".") -> #DIV/0! | Q2: A_low1 | R2: =SLOPE(Tables!$F$69:$F$73,Tables!$G$69:$G$73) -> #DIV/0! | S2: A_low2 | T2: =SLOPE(Tables!$N$69:$N$73,Tables!$O$69:$O$73) -> #DIV/0!
H3: B_high (Low1) | I3: =INTERCEPT(Tables!$B$69:$B$73,Tables!$C$69:$C$73) -> #DIV/0! | J3: =REPLACE(I3,2,1,".") -> #DIV/0! | Q3: B_low1 | R3: =INTERCEPT(Tables!$F$69:$F$73,Tables!$G$69:$G$73) -> #DIV/0! | S3: B_low2 | T3: =INTERCEPT(Tables!$N$69:$N$73,Tables!$O$69:$O$73) -> #DIV/0!
H4: C_high (Low1) | I4: =SLOPE(Tables!$D$69:$D$73,Tables!$E$69:$E$73) -> #DIV/0! | J4: =REPLACE(I4,2,1,".") -> #DIV/0! | Q4: C_low1 | R4: =SLOPE(Tables!$H$69:$H$73,Tables!$I$69:$I$73) -> #DIV/0! | S4: C_low2 | T4: =SLOPE(Tables!$P$69:$P$73,Tables!$Q$69:$Q$73) -> #DIV/0!
H5: D_high (Low1) | I5: =INTERCEPT(Tables!$D$69:$D$73,Tables!$E$69:$E$73) -> #DIV/0! | J5: =REPLACE(I5,3,1,".") -> #DIV/0! | Q5: D_low1 | R5: =INTERCEPT(Tables!$H$69:$H$73,Tables!$I$69:$I$73) -> #DIV/0! | S5: D_low2 | T5: =INTERCEPT(Tables!$P$69:$P$73,Tables!$Q$69:$Q$73) -> #DIV/0!
H7: A_high (Low2) | I7: =SLOPE(Tables!$J$69:$J$73,Tables!$K$69:$K$73) -> #DIV/0! | J7: =SUBSTITUTE(I7&"",",",".") -> #DIV/0! | R7: =REPLACE(R2,2,1,".") -> #DIV/0! | T7: =REPLACE(T2,2,1,".") -> #DIV/0!
H8: B_high (Low2) | I8: =INTERCEPT(Tables!$J$69:$J$73,Tables!$K$69:$K$73) -> #DIV/0! | J8: =SUBSTITUTE(I8&"",",",".") -> #DIV/0! | R8: =REPLACE(R3,4,1,".") -> #DIV/0! | T8: =REPLACE(T3,4,1,".") -> #DIV/0!
H9: C_high (Low2) | I9: =SLOPE(Tables!$L$69:$L$73,Tables!$M$69:$M$73) -> #DIV/0! | J9: =SUBSTITUTE(I9&"",",",".") -> #DIV/0! | R9: =REPLACE(R4,2,1,".") -> #DIV/0! | T9: =REPLACE(T4,2,1,".") -> #DIV/0!
H10: D_high (Low2) | I10: =INTERCEPT(Tables!$L$69:$L$73,Tables!$M$69:$M$73) -> #DIV/0! | J10: =SUBSTITUTE(I10&"",",",".") -> #DIV/0! | R10: =REPLACE(R5,3,1,".") -> #DIV/0! | T10: =REPLACE(T5,3,1,".") -> #DIV/0!
H12: Low2 - Low1
H13: A_high (%) | I13: =IFERROR((I7-I2)/I2,"")
H14: B_high | I14: =IFERROR(I8-I3,"")
H15: C_high (%) | I15: =IFERROR((I9-I4)/I4,"")
H16: D_high | I16: =IFERROR(I10-I5,"")
B32: Lines to paste in setup_routine() (V_HIGH and I_HIGH from the Low1 run):
B33: =IFERROR("shield.sensors.setConversionParametersLinear(V_HIGH, "&SUBSTITUTE(I2&"",",",".")&IF(I2=INT(I2),".0","")&"F"&", "&SUBSTITUTE(I3&"",",",".")&IF(I3=INT(I3),".0","")&"F"&");","// V_HIGH: no data yet") -> // V_HIGH: no data yet
B34: =IFERROR("shield.sensors.setConversionParametersLinear(I_HIGH, "&SUBSTITUTE(I4&"",",",".")&IF(I4=INT(I4),".0","")&"F"&", "&SUBSTITUTE(I5&"",",",".")&IF(I5=INT(I5),".0","")&"F"&");","// I_HIGH: no data yet") -> // I_HIGH: no data yet
B35: =IFERROR("shield.sensors.setConversionParametersLinear(V1_LOW, "&SUBSTITUTE(R2&"",",",".")&IF(R2=INT(R2),".0","")&"F"&", "&SUBSTITUTE(R3&"",",",".")&IF(R3=INT(R3),".0","")&"F"&");","// V1_LOW: no data yet") -> // V1_LOW: no data yet
B36: =IFERROR("shield.sensors.setConversionParametersLinear(I1_LOW, "&SUBSTITUTE(R4&"",",",".")&IF(R4=INT(R4),".0","")&"F"&", "&SUBSTITUTE(R5&"",",",".")&IF(R5=INT(R5),".0","")&"F"&");","// I1_LOW: no data yet") -> // I1_LOW: no data yet
B37: =IFERROR("shield.sensors.setConversionParametersLinear(V2_LOW, "&SUBSTITUTE(T2&"",",",".")&IF(T2=INT(T2),".0","")&"F"&", "&SUBSTITUTE(T3&"",",",".")&IF(T3=INT(T3),".0","")&"F"&");","// V2_LOW: no data yet") -> // V2_LOW: no data yet
B38: =IFERROR("shield.sensors.setConversionParametersLinear(I2_LOW, "&SUBSTITUTE(T4&"",",",".")&IF(T4=INT(T4),".0","")&"F"&", "&SUBSTITUTE(T5&"",",",".")&IF(T5=INT(T5),".0","")&"F"&");","// I2_LOW: no data yet") -> // I2_LOW: no data yet
B40: Alternative V_HIGH and I_HIGH lines (Low2 run):
B41: =IFERROR("shield.sensors.setConversionParametersLinear(V_HIGH, "&SUBSTITUTE(I7&"",",",".")&IF(I7=INT(I7),".0","")&"F"&", "&SUBSTITUTE(I8&"",",",".")&IF(I8=INT(I8),".0","")&"F"&");","// V_HIGH: no data yet") -> // V_HIGH: no data yet
B42: =IFERROR("shield.sensors.setConversionParametersLinear(I_HIGH, "&SUBSTITUTE(I9&"",",",".")&IF(I9=INT(I9),".0","")&"F"&", "&SUBSTITUTE(I10&"",",",".")&IF(I10=INT(I10),".0","")&"F"&");","// I_HIGH: no data yet") -> // I_HIGH: no data yet

Sheet Curves Board 10
H2: A_high (Low1) | I2: =SLOPE(Tables!$B$77:$B$81,Tables!$C$77:$C$81) -> #DIV/0! | J2: =REPLACE(I2,2,1,".") -> #DIV/0! | Q2: A_low1 | R2: =SLOPE(Tables!$F$77:$F$81,Tables!$G$77:$G$81) -> #DIV/0! | S2: A_low2 | T2: =SLOPE(Tables!$N$77:$N$81,Tables!$O$77:$O$81) -> #DIV/0!
H3: B_high (Low1) | I3: =INTERCEPT(Tables!$B$77:$B$81,Tables!$C$77:$C$81) -> #DIV/0! | J3: =REPLACE(I3,2,1,".") -> #DIV/0! | Q3: B_low1 | R3: =INTERCEPT(Tables!$F$77:$F$81,Tables!$G$77:$G$81) -> #DIV/0! | S3: B_low2 | T3: =INTERCEPT(Tables!$N$77:$N$81,Tables!$O$77:$O$81) -> #DIV/0!
H4: C_high (Low1) | I4: =SLOPE(Tables!$D$77:$D$81,Tables!$E$77:$E$81) -> #DIV/0! | J4: =REPLACE(I4,2,1,".") -> #DIV/0! | Q4: C_low1 | R4: =SLOPE(Tables!$H$77:$H$81,Tables!$I$77:$I$81) -> #DIV/0! | S4: C_low2 | T4: =SLOPE(Tables!$P$77:$P$81,Tables!$Q$77:$Q$81) -> #DIV/0!
H5: D_high (Low1) | I5: =INTERCEPT(Tables!$D$77:$D$81,Tables!$E$77:$E$81) -> #DIV/0! | J5: =REPLACE(I5,3,1,".") -> #DIV/0! | Q5: D_low1 | R5: =INTERCEPT(Tables!$H$77:$H$81,Tables!$I$77:$I$81) -> #DIV/0! | S5: D_low2 | T5: =INTERCEPT(Tables!$P$77:$P$81,Tables!$Q$77:$Q$81) -> #DIV/0!
H7: A_high (Low2) | I7: =SLOPE(Tables!$J$77:$J$81,Tables!$K$77:$K$81) -> #DIV/0! | J7: =SUBSTITUTE(I7&"",",",".") -> #DIV/0! | R7: =REPLACE(R2,2,1,".") -> #DIV/0! | T7: =REPLACE(T2,2,1,".") -> #DIV/0!
H8: B_high (Low2) | I8: =INTERCEPT(Tables!$J$77:$J$81,Tables!$K$77:$K$81) -> #DIV/0! | J8: =SUBSTITUTE(I8&"",",",".") -> #DIV/0! | R8: =REPLACE(R3,4,1,".") -> #DIV/0! | T8: =REPLACE(T3,4,1,".") -> #DIV/0!
H9: C_high (Low2) | I9: =SLOPE(Tables!$L$77:$L$81,Tables!$M$77:$M$81) -> #DIV/0! | J9: =SUBSTITUTE(I9&"",",",".") -> #DIV/0! | R9: =REPLACE(R4,2,1,".") -> #DIV/0! | T9: =REPLACE(T4,2,1,".") -> #DIV/0!
H10: D_high (Low2) | I10: =INTERCEPT(Tables!$L$77:$L$81,Tables!$M$77:$M$81) -> #DIV/0! | J10: =SUBSTITUTE(I10&"",",",".") -> #DIV/0! | R10: =REPLACE(R5,3,1,".") -> #DIV/0! | T10: =REPLACE(T5,3,1,".") -> #DIV/0!
H12: Low2 - Low1
H13: A_high (%) | I13: =IFERROR((I7-I2)/I2,"")
H14: B_high | I14: =IFERROR(I8-I3,"")
H15: C_high (%) | I15: =IFERROR((I9-I4)/I4,"")
H16: D_high | I16: =IFERROR(I10-I5,"")
B32: Lines to paste in setup_routine() (V_HIGH and I_HIGH from the Low1 run):
B33: =IFERROR("shield.sensors.setConversionParametersLinear(V_HIGH, "&SUBSTITUTE(I2&"",",",".")&IF(I2=INT(I2),".0","")&"F"&", "&SUBSTITUTE(I3&"",",",".")&IF(I3=INT(I3),".0","")&"F"&");","// V_HIGH: no data yet") -> // V_HIGH: no data yet
B34: =IFERROR("shield.sensors.setConversionParametersLinear(I_HIGH, "&SUBSTITUTE(I4&"",",",".")&IF(I4=INT(I4),".0","")&"F"&", "&SUBSTITUTE(I5&"",",",".")&IF(I5=INT(I5),".0","")&"F"&");","// I_HIGH: no data yet") -> // I_HIGH: no data yet
B35: =IFERROR("shield.sensors.setConversionParametersLinear(V1_LOW, "&SUBSTITUTE(R2&"",",",".")&IF(R2=INT(R2),".0","")&"F"&", "&SUBSTITUTE(R3&"",",",".")&IF(R3=INT(R3),".0","")&"F"&");","// V1_LOW: no data yet") -> // V1_LOW: no data yet
B36: =IFERROR("shield.sensors.setConversionParametersLinear(I1_LOW, "&SUBSTITUTE(R4&"",",",".")&IF(R4=INT(R4),".0","")&"F"&", "&SUBSTITUTE(R5&"",",",".")&IF(R5=INT(R5),".0","")&"F"&");","// I1_LOW: no data yet") -> // I1_LOW: no data yet
B37: =IFERROR("shield.sensors.setConversionParametersLinear(V2_LOW, "&SUBSTITUTE(T2&"",",",".")&IF(T2=INT(T2),".0","")&"F"&", "&SUBSTITUTE(T3&"",",",".")&IF(T3=INT(T3),".0","")&"F"&");","// V2_LOW: no data yet") -> // V2_LOW: no data yet
B38: =IFERROR("shield.sensors.setConversionParametersLinear(I2_LOW, "&SUBSTITUTE(T4&"",",",".")&IF(T4=INT(T4),".0","")&"F"&", "&SUBSTITUTE(T5&"",",",".")&IF(T5=INT(T5),".0","")&"F"&");","// I2_LOW: no data yet") -> // I2_LOW: no data yet
B40: Alternative V_HIGH and I_HIGH lines (Low2 run):
B41: =IFERROR("shield.sensors.setConversionParametersLinear(V_HIGH, "&SUBSTITUTE(I7&"",",",".")&IF(I7=INT(I7),".0","")&"F"&", "&SUBSTITUTE(I8&"",",",".")&IF(I8=INT(I8),".0","")&"F"&");","// V_HIGH: no data yet") -> // V_HIGH: no data yet
B42: =IFERROR("shield.sensors.setConversionParametersLinear(I_HIGH, "&SUBSTITUTE(I9&"",",",".")&IF(I9=INT(I9),".0","")&"F"&", "&SUBSTITUTE(I10&"",",",".")&IF(I10=INT(I10),".0","")&"F"&");","// I_HIGH: no data yet") -> // I_HIGH: no data yet

Sheet Curves Board 11
H2: A_high (Low1) | I2: =SLOPE(Tables!$B$85:$B$89,Tables!$C$85:$C$89) -> #DIV/0! | J2: =REPLACE(I2,2,1,".") -> #DIV/0! | Q2: A_low1 | R2: =SLOPE(Tables!$F$85:$F$89,Tables!$G$85:$G$89) -> #DIV/0! | S2: A_low2 | T2: =SLOPE(Tables!$N$85:$N$89,Tables!$O$85:$O$89) -> #DIV/0!
H3: B_high (Low1) | I3: =INTERCEPT(Tables!$B$85:$B$89,Tables!$C$85:$C$89) -> #DIV/0! | J3: =REPLACE(I3,2,1,".") -> #DIV/0! | Q3: B_low1 | R3: =INTERCEPT(Tables!$F$85:$F$89,Tables!$G$85:$G$89) -> #DIV/0! | S3: B_low2 | T3: =INTERCEPT(Tables!$N$85:$N$89,Tables!$O$85:$O$89) -> #DIV/0!
H4: C_high (Low1) | I4: =SLOPE(Tables!$D$85:$D$89,Tables!$E$85:$E$89) -> #DIV/0! | J4: =REPLACE(I4,2,1,".") -> #DIV/0! | Q4: C_low1 | R4: =SLOPE(Tables!$H$85:$H$89,Tables!$I$85:$I$89) -> #DIV/0! | S4: C_low2 | T4: =SLOPE(Tables!$P$85:$P$89,Tables!$Q$85:$Q$89) -> #DIV/0!
H5: D_high (Low1) | I5: =INTERCEPT(Tables!$D$85:$D$89,Tables!$E$85:$E$89) -> #DIV/0! | J5: =REPLACE(I5,3,1,".") -> #DIV/0! | Q5: D_low1 | R5: =INTERCEPT(Tables!$H$85:$H$89,Tables!$I$85:$I$89) -> #DIV/0! | S5: D_low2 | T5: =INTERCEPT(Tables!$P$85:$P$89,Tables!$Q$85:$Q$89) -> #DIV/0!
H7: A_high (Low2) | I7: =SLOPE(Tables!$J$85:$J$89,Tables!$K$85:$K$89) -> #DIV/0! | J7: =SUBSTITUTE(I7&"",",",".") -> #DIV/0! | R7: =REPLACE(R2,2,1,".") -> #DIV/0! | T7: =REPLACE(T2,2,1,".") -> #DIV/0!
H8: B_high (Low2) | I8: =INTERCEPT(Tables!$J$85:$J$89,Tables!$K$85:$K$89) -> #DIV/0! | J8: =SUBSTITUTE(I8&"",",",".") -> #DIV/0! | R8: =REPLACE(R3,4,1,".") -> #DIV/0! | T8: =REPLACE(T3,4,1,".") -> #DIV/0!
